
2022-06-01 19:42:43,641 INFO: errors [in C:\Users\georg\OneDrive\Desktop\Projects\FSND\projects\01_fyyur\starter_code\app.py:413]
2022-06-07 14:42:24,568 INFO: errors [in C:\Users\georg\OneDrive\Desktop\Projects\FSND\projects\01_fyyur\starter_code\app.py:490]
2022-06-07 14:43:40,763 INFO: errors [in C:\Users\georg\OneDrive\Desktop\Projects\FSND\projects\01_fyyur\starter_code\app.py:490]
2022-06-07 14:44:49,960 INFO: errors [in C:\Users\georg\OneDrive\Desktop\Projects\FSND\projects\01_fyyur\starter_code\app.py:490]
2022-06-07 14:48:31,583 INFO: errors [in C:\Users\georg\OneDrive\Desktop\Projects\FSND\projects\01_fyyur\starter_code\app.py:491]
2022-06-07 14:49:54,788 INFO: errors [in C:\Users\georg\OneDrive\Desktop\Projects\FSND\projects\01_fyyur\starter_code\app.py:491]
2022-06-07 14:51:12,869 INFO: errors [in C:\Users\georg\OneDrive\Desktop\Projects\FSND\projects\01_fyyur\starter_code\app.py:491]
2022-06-07 15:00:27,453 INFO: errors [in C:\Users\georg\OneDrive\Desktop\Projects\FSND\projects\01_fyyur\starter_code\app.py:491]
2022-06-07 15:03:27,057 INFO: errors [in C:\Users\georg\OneDrive\Desktop\Projects\FSND\projects\01_fyyur\starter_code\app.py:491]
2022-06-07 15:08:38,593 INFO: errors [in C:\Users\georg\OneDrive\Desktop\Projects\FSND\projects\01_fyyur\starter_code\app.py:491]
2022-06-07 15:08:41,082 INFO: errors [in C:\Users\georg\OneDrive\Desktop\Projects\FSND\projects\01_fyyur\starter_code\app.py:491]
2022-06-07 15:56:23,567 INFO: errors [in C:\Users\georg\OneDrive\Desktop\Projects\FSND\projects\01_fyyur\starter_code\app.py:479]
2022-06-07 15:56:27,285 ERROR: Exception on / [GET] [in C:\Users\georg\OneDrive\Desktop\Projects\FSND\projects\01_fyyur\starter_code\lib\site-packages\flask\app.py:1455]
Traceback (most recent call last):
  File "C:\Users\georg\OneDrive\Desktop\Projects\FSND\projects\01_fyyur\starter_code\lib\site-packages\sqlalchemy\engine\base.py", line 1819, in _execute_context
    self.dialect.do_execute(
  File "C:\Users\georg\OneDrive\Desktop\Projects\FSND\projects\01_fyyur\starter_code\lib\site-packages\sqlalchemy\engine\default.py", line 732, in do_execute
    cursor.execute(statement, parameters)
sqlite3.OperationalError: no such table: artist

The above exception was the direct cause of the following exception:

Traceback (most recent call last):
  File "C:\Users\georg\OneDrive\Desktop\Projects\FSND\projects\01_fyyur\starter_code\lib\site-packages\flask\app.py", line 2077, in wsgi_app
    response = self.full_dispatch_request()
  File "C:\Users\georg\OneDrive\Desktop\Projects\FSND\projects\01_fyyur\starter_code\lib\site-packages\flask\app.py", line 1525, in full_dispatch_request
    rv = self.handle_user_exception(e)
  File "C:\Users\georg\OneDrive\Desktop\Projects\FSND\projects\01_fyyur\starter_code\lib\site-packages\flask\app.py", line 1523, in full_dispatch_request
    rv = self.dispatch_request()
  File "C:\Users\georg\OneDrive\Desktop\Projects\FSND\projects\01_fyyur\starter_code\lib\site-packages\flask\app.py", line 1509, in dispatch_request
    return self.ensure_sync(self.view_functions[rule.endpoint])(**req.view_args)
  File "C:\Users\georg\OneDrive\Desktop\Projects\FSND\projects\01_fyyur\starter_code\app.py", line 61, in index
    recent_artists = Artist.query.order_by(Artist.id.desc()).limit(3).all()
  File "C:\Users\georg\OneDrive\Desktop\Projects\FSND\projects\01_fyyur\starter_code\lib\site-packages\sqlalchemy\orm\query.py", line 2768, in all
    return self._iter().all()
  File "C:\Users\georg\OneDrive\Desktop\Projects\FSND\projects\01_fyyur\starter_code\lib\site-packages\sqlalchemy\orm\query.py", line 2903, in _iter
    result = self.session.execute(
  File "C:\Users\georg\OneDrive\Desktop\Projects\FSND\projects\01_fyyur\starter_code\lib\site-packages\sqlalchemy\orm\session.py", line 1696, in execute
    result = conn._execute_20(statement, params or {}, execution_options)
  File "C:\Users\georg\OneDrive\Desktop\Projects\FSND\projects\01_fyyur\starter_code\lib\site-packages\sqlalchemy\engine\base.py", line 1631, in _execute_20
    return meth(self, args_10style, kwargs_10style, execution_options)
  File "C:\Users\georg\OneDrive\Desktop\Projects\FSND\projects\01_fyyur\starter_code\lib\site-packages\sqlalchemy\sql\elements.py", line 325, in _execute_on_connection
    return connection._execute_clauseelement(
  File "C:\Users\georg\OneDrive\Desktop\Projects\FSND\projects\01_fyyur\starter_code\lib\site-packages\sqlalchemy\engine\base.py", line 1498, in _execute_clauseelement
    ret = self._execute_context(
  File "C:\Users\georg\OneDrive\Desktop\Projects\FSND\projects\01_fyyur\starter_code\lib\site-packages\sqlalchemy\engine\base.py", line 1862, in _execute_context
    self._handle_dbapi_exception(
  File "C:\Users\georg\OneDrive\Desktop\Projects\FSND\projects\01_fyyur\starter_code\lib\site-packages\sqlalchemy\engine\base.py", line 2043, in _handle_dbapi_exception
    util.raise_(
  File "C:\Users\georg\OneDrive\Desktop\Projects\FSND\projects\01_fyyur\starter_code\lib\site-packages\sqlalchemy\util\compat.py", line 207, in raise_
    raise exception
  File "C:\Users\georg\OneDrive\Desktop\Projects\FSND\projects\01_fyyur\starter_code\lib\site-packages\sqlalchemy\engine\base.py", line 1819, in _execute_context
    self.dialect.do_execute(
  File "C:\Users\georg\OneDrive\Desktop\Projects\FSND\projects\01_fyyur\starter_code\lib\site-packages\sqlalchemy\engine\default.py", line 732, in do_execute
    cursor.execute(statement, parameters)
sqlalchemy.exc.OperationalError: (sqlite3.OperationalError) no such table: artist
[SQL: SELECT artist.id AS artist_id, artist.name AS artist_name, artist.city AS artist_city, artist.state AS artist_state, artist.phone AS artist_phone, artist.genres AS artist_genres, artist.image_link AS artist_image_link, artist.website_link AS artist_website_link, artist.facebook_link AS artist_facebook_link, artist.seeking_venue AS artist_seeking_venue, artist.seeking_description AS artist_seeking_description 
FROM artist ORDER BY artist.id DESC
 LIMIT ? OFFSET ?]
[parameters: (3, 0)]
(Background on this error at: https://sqlalche.me/e/14/e3q8)
2022-06-07 15:56:27,548 ERROR: Exception on /favicon.ico [GET] [in C:\Users\georg\OneDrive\Desktop\Projects\FSND\projects\01_fyyur\starter_code\lib\site-packages\flask\app.py:1455]
Traceback (most recent call last):
  File "C:\Users\georg\OneDrive\Desktop\Projects\FSND\projects\01_fyyur\starter_code\lib\site-packages\flask\app.py", line 1523, in full_dispatch_request
    rv = self.dispatch_request()
  File "C:\Users\georg\OneDrive\Desktop\Projects\FSND\projects\01_fyyur\starter_code\lib\site-packages\flask\app.py", line 1499, in dispatch_request
    self.raise_routing_exception(req)
  File "C:\Users\georg\OneDrive\Desktop\Projects\FSND\projects\01_fyyur\starter_code\lib\site-packages\flask\app.py", line 1481, in raise_routing_exception
    raise request.routing_exception  # type: ignore
  File "C:\Users\georg\OneDrive\Desktop\Projects\FSND\projects\01_fyyur\starter_code\lib\site-packages\flask\ctx.py", line 397, in match_request
    result = self.url_adapter.match(return_rule=True)  # type: ignore
  File "C:\Users\georg\OneDrive\Desktop\Projects\FSND\projects\01_fyyur\starter_code\lib\site-packages\werkzeug\routing.py", line 2028, in match
    raise NotFound()
werkzeug.exceptions.NotFound: 404 Not Found: The requested URL was not found on the server. If you entered the URL manually please check your spelling and try again.

During handling of the above exception, another exception occurred:

Traceback (most recent call last):
  File "C:\Users\georg\OneDrive\Desktop\Projects\FSND\projects\01_fyyur\starter_code\lib\site-packages\flask\app.py", line 2077, in wsgi_app
    response = self.full_dispatch_request()
  File "C:\Users\georg\OneDrive\Desktop\Projects\FSND\projects\01_fyyur\starter_code\lib\site-packages\flask\app.py", line 1525, in full_dispatch_request
    rv = self.handle_user_exception(e)
  File "C:\Users\georg\OneDrive\Desktop\Projects\FSND\projects\01_fyyur\starter_code\lib\site-packages\flask\app.py", line 1384, in handle_user_exception
    return self.handle_http_exception(e)
  File "C:\Users\georg\OneDrive\Desktop\Projects\FSND\projects\01_fyyur\starter_code\lib\site-packages\flask\app.py", line 1324, in handle_http_exception
    return self.ensure_sync(handler)(e)
  File "C:\Users\georg\OneDrive\Desktop\Projects\FSND\projects\01_fyyur\starter_code\app.py", line 451, in not_found_error
    return render_template('errors/404.html'), 404
  File "C:\Users\georg\OneDrive\Desktop\Projects\FSND\projects\01_fyyur\starter_code\lib\site-packages\flask\templating.py", line 148, in render_template
    return _render(
  File "C:\Users\georg\OneDrive\Desktop\Projects\FSND\projects\01_fyyur\starter_code\lib\site-packages\flask\templating.py", line 128, in _render
    rv = template.render(context)
  File "C:\Users\georg\OneDrive\Desktop\Projects\FSND\projects\01_fyyur\starter_code\lib\site-packages\jinja2\environment.py", line 1289, in render
    self.environment.handle_exception()
  File "C:\Users\georg\OneDrive\Desktop\Projects\FSND\projects\01_fyyur\starter_code\lib\site-packages\jinja2\environment.py", line 924, in handle_exception
    raise rewrite_traceback_stack(source=source)
  File "C:\Users\georg\OneDrive\Desktop\Projects\FSND\projects\01_fyyur\starter_code\templates\errors\404.html", line 1, in <module>
    {% extends 'layouts/main.html' %}
  File "C:\Users\georg\OneDrive\Desktop\Projects\FSND\projects\01_fyyur\starter_code\templates\layouts\main.html", line 81, in <module>
    <li {% if request.endpoint == 'venues' %} class="active" {% endif %}><a href="{{ url_for('venues') }}">Venues</a></li>
  File "C:\Users\georg\OneDrive\Desktop\Projects\FSND\projects\01_fyyur\starter_code\lib\site-packages\flask\helpers.py", line 336, in url_for
    return appctx.app.handle_url_build_error(error, endpoint, values)
  File "C:\Users\georg\OneDrive\Desktop\Projects\FSND\projects\01_fyyur\starter_code\lib\site-packages\flask\helpers.py", line 323, in url_for
    rv = url_adapter.build(
  File "C:\Users\georg\OneDrive\Desktop\Projects\FSND\projects\01_fyyur\starter_code\lib\site-packages\werkzeug\routing.py", line 2301, in build
    raise BuildError(endpoint, values, method, self)
werkzeug.routing.BuildError: Could not build url for endpoint 'venues'. Did you mean 'venue.venues' instead?
2022-06-07 15:57:33,544 ERROR: Exception on / [GET] [in C:\Users\georg\OneDrive\Desktop\Projects\FSND\projects\01_fyyur\starter_code\lib\site-packages\flask\app.py:1455]
Traceback (most recent call last):
  File "C:\Users\georg\OneDrive\Desktop\Projects\FSND\projects\01_fyyur\starter_code\lib\site-packages\sqlalchemy\engine\base.py", line 1819, in _execute_context
    self.dialect.do_execute(
  File "C:\Users\georg\OneDrive\Desktop\Projects\FSND\projects\01_fyyur\starter_code\lib\site-packages\sqlalchemy\engine\default.py", line 732, in do_execute
    cursor.execute(statement, parameters)
sqlite3.OperationalError: no such table: artist

The above exception was the direct cause of the following exception:

Traceback (most recent call last):
  File "C:\Users\georg\OneDrive\Desktop\Projects\FSND\projects\01_fyyur\starter_code\lib\site-packages\flask\app.py", line 2077, in wsgi_app
    response = self.full_dispatch_request()
  File "C:\Users\georg\OneDrive\Desktop\Projects\FSND\projects\01_fyyur\starter_code\lib\site-packages\flask\app.py", line 1525, in full_dispatch_request
    rv = self.handle_user_exception(e)
  File "C:\Users\georg\OneDrive\Desktop\Projects\FSND\projects\01_fyyur\starter_code\lib\site-packages\flask\app.py", line 1523, in full_dispatch_request
    rv = self.dispatch_request()
  File "C:\Users\georg\OneDrive\Desktop\Projects\FSND\projects\01_fyyur\starter_code\lib\site-packages\flask\app.py", line 1509, in dispatch_request
    return self.ensure_sync(self.view_functions[rule.endpoint])(**req.view_args)
  File "C:\Users\georg\OneDrive\Desktop\Projects\FSND\projects\01_fyyur\starter_code\app.py", line 61, in index
    recent_artists = Artist.query.order_by(Artist.id.desc()).limit(3).all()
  File "C:\Users\georg\OneDrive\Desktop\Projects\FSND\projects\01_fyyur\starter_code\lib\site-packages\sqlalchemy\orm\query.py", line 2768, in all
    return self._iter().all()
  File "C:\Users\georg\OneDrive\Desktop\Projects\FSND\projects\01_fyyur\starter_code\lib\site-packages\sqlalchemy\orm\query.py", line 2903, in _iter
    result = self.session.execute(
  File "C:\Users\georg\OneDrive\Desktop\Projects\FSND\projects\01_fyyur\starter_code\lib\site-packages\sqlalchemy\orm\session.py", line 1696, in execute
    result = conn._execute_20(statement, params or {}, execution_options)
  File "C:\Users\georg\OneDrive\Desktop\Projects\FSND\projects\01_fyyur\starter_code\lib\site-packages\sqlalchemy\engine\base.py", line 1631, in _execute_20
    return meth(self, args_10style, kwargs_10style, execution_options)
  File "C:\Users\georg\OneDrive\Desktop\Projects\FSND\projects\01_fyyur\starter_code\lib\site-packages\sqlalchemy\sql\elements.py", line 325, in _execute_on_connection
    return connection._execute_clauseelement(
  File "C:\Users\georg\OneDrive\Desktop\Projects\FSND\projects\01_fyyur\starter_code\lib\site-packages\sqlalchemy\engine\base.py", line 1498, in _execute_clauseelement
    ret = self._execute_context(
  File "C:\Users\georg\OneDrive\Desktop\Projects\FSND\projects\01_fyyur\starter_code\lib\site-packages\sqlalchemy\engine\base.py", line 1862, in _execute_context
    self._handle_dbapi_exception(
  File "C:\Users\georg\OneDrive\Desktop\Projects\FSND\projects\01_fyyur\starter_code\lib\site-packages\sqlalchemy\engine\base.py", line 2043, in _handle_dbapi_exception
    util.raise_(
  File "C:\Users\georg\OneDrive\Desktop\Projects\FSND\projects\01_fyyur\starter_code\lib\site-packages\sqlalchemy\util\compat.py", line 207, in raise_
    raise exception
  File "C:\Users\georg\OneDrive\Desktop\Projects\FSND\projects\01_fyyur\starter_code\lib\site-packages\sqlalchemy\engine\base.py", line 1819, in _execute_context
    self.dialect.do_execute(
  File "C:\Users\georg\OneDrive\Desktop\Projects\FSND\projects\01_fyyur\starter_code\lib\site-packages\sqlalchemy\engine\default.py", line 732, in do_execute
    cursor.execute(statement, parameters)
sqlalchemy.exc.OperationalError: (sqlite3.OperationalError) no such table: artist
[SQL: SELECT artist.id AS artist_id, artist.name AS artist_name, artist.city AS artist_city, artist.state AS artist_state, artist.phone AS artist_phone, artist.genres AS artist_genres, artist.image_link AS artist_image_link, artist.website_link AS artist_website_link, artist.facebook_link AS artist_facebook_link, artist.seeking_venue AS artist_seeking_venue, artist.seeking_description AS artist_seeking_description 
FROM artist ORDER BY artist.id DESC
 LIMIT ? OFFSET ?]
[parameters: (3, 0)]
(Background on this error at: https://sqlalche.me/e/14/e3q8)
2022-06-07 15:57:33,677 ERROR: Exception on /favicon.ico [GET] [in C:\Users\georg\OneDrive\Desktop\Projects\FSND\projects\01_fyyur\starter_code\lib\site-packages\flask\app.py:1455]
Traceback (most recent call last):
  File "C:\Users\georg\OneDrive\Desktop\Projects\FSND\projects\01_fyyur\starter_code\lib\site-packages\flask\app.py", line 1523, in full_dispatch_request
    rv = self.dispatch_request()
  File "C:\Users\georg\OneDrive\Desktop\Projects\FSND\projects\01_fyyur\starter_code\lib\site-packages\flask\app.py", line 1499, in dispatch_request
    self.raise_routing_exception(req)
  File "C:\Users\georg\OneDrive\Desktop\Projects\FSND\projects\01_fyyur\starter_code\lib\site-packages\flask\app.py", line 1481, in raise_routing_exception
    raise request.routing_exception  # type: ignore
  File "C:\Users\georg\OneDrive\Desktop\Projects\FSND\projects\01_fyyur\starter_code\lib\site-packages\flask\ctx.py", line 397, in match_request
    result = self.url_adapter.match(return_rule=True)  # type: ignore
  File "C:\Users\georg\OneDrive\Desktop\Projects\FSND\projects\01_fyyur\starter_code\lib\site-packages\werkzeug\routing.py", line 2028, in match
    raise NotFound()
werkzeug.exceptions.NotFound: 404 Not Found: The requested URL was not found on the server. If you entered the URL manually please check your spelling and try again.

During handling of the above exception, another exception occurred:

Traceback (most recent call last):
  File "C:\Users\georg\OneDrive\Desktop\Projects\FSND\projects\01_fyyur\starter_code\lib\site-packages\flask\app.py", line 2077, in wsgi_app
    response = self.full_dispatch_request()
  File "C:\Users\georg\OneDrive\Desktop\Projects\FSND\projects\01_fyyur\starter_code\lib\site-packages\flask\app.py", line 1525, in full_dispatch_request
    rv = self.handle_user_exception(e)
  File "C:\Users\georg\OneDrive\Desktop\Projects\FSND\projects\01_fyyur\starter_code\lib\site-packages\flask\app.py", line 1384, in handle_user_exception
    return self.handle_http_exception(e)
  File "C:\Users\georg\OneDrive\Desktop\Projects\FSND\projects\01_fyyur\starter_code\lib\site-packages\flask\app.py", line 1324, in handle_http_exception
    return self.ensure_sync(handler)(e)
  File "C:\Users\georg\OneDrive\Desktop\Projects\FSND\projects\01_fyyur\starter_code\app.py", line 451, in not_found_error
    return render_template('errors/404.html'), 404
  File "C:\Users\georg\OneDrive\Desktop\Projects\FSND\projects\01_fyyur\starter_code\lib\site-packages\flask\templating.py", line 148, in render_template
    return _render(
  File "C:\Users\georg\OneDrive\Desktop\Projects\FSND\projects\01_fyyur\starter_code\lib\site-packages\flask\templating.py", line 128, in _render
    rv = template.render(context)
  File "C:\Users\georg\OneDrive\Desktop\Projects\FSND\projects\01_fyyur\starter_code\lib\site-packages\jinja2\environment.py", line 1289, in render
    self.environment.handle_exception()
  File "C:\Users\georg\OneDrive\Desktop\Projects\FSND\projects\01_fyyur\starter_code\lib\site-packages\jinja2\environment.py", line 924, in handle_exception
    raise rewrite_traceback_stack(source=source)
  File "C:\Users\georg\OneDrive\Desktop\Projects\FSND\projects\01_fyyur\starter_code\templates\errors\404.html", line 1, in <module>
    {% extends 'layouts/main.html' %}
  File "C:\Users\georg\OneDrive\Desktop\Projects\FSND\projects\01_fyyur\starter_code\templates\layouts\main.html", line 81, in <module>
    <li {% if request.endpoint == 'venues' %} class="active" {% endif %}><a href="{{ url_for('venues') }}">Venues</a></li>
  File "C:\Users\georg\OneDrive\Desktop\Projects\FSND\projects\01_fyyur\starter_code\lib\site-packages\flask\helpers.py", line 336, in url_for
    return appctx.app.handle_url_build_error(error, endpoint, values)
  File "C:\Users\georg\OneDrive\Desktop\Projects\FSND\projects\01_fyyur\starter_code\lib\site-packages\flask\helpers.py", line 323, in url_for
    rv = url_adapter.build(
  File "C:\Users\georg\OneDrive\Desktop\Projects\FSND\projects\01_fyyur\starter_code\lib\site-packages\werkzeug\routing.py", line 2301, in build
    raise BuildError(endpoint, values, method, self)
werkzeug.routing.BuildError: Could not build url for endpoint 'venues'. Did you mean 'venue.venues' instead?
2022-06-07 15:57:36,118 ERROR: Exception on / [GET] [in C:\Users\georg\OneDrive\Desktop\Projects\FSND\projects\01_fyyur\starter_code\lib\site-packages\flask\app.py:1455]
Traceback (most recent call last):
  File "C:\Users\georg\OneDrive\Desktop\Projects\FSND\projects\01_fyyur\starter_code\lib\site-packages\sqlalchemy\engine\base.py", line 1819, in _execute_context
    self.dialect.do_execute(
  File "C:\Users\georg\OneDrive\Desktop\Projects\FSND\projects\01_fyyur\starter_code\lib\site-packages\sqlalchemy\engine\default.py", line 732, in do_execute
    cursor.execute(statement, parameters)
sqlite3.OperationalError: no such table: artist

The above exception was the direct cause of the following exception:

Traceback (most recent call last):
  File "C:\Users\georg\OneDrive\Desktop\Projects\FSND\projects\01_fyyur\starter_code\lib\site-packages\flask\app.py", line 2077, in wsgi_app
    response = self.full_dispatch_request()
  File "C:\Users\georg\OneDrive\Desktop\Projects\FSND\projects\01_fyyur\starter_code\lib\site-packages\flask\app.py", line 1525, in full_dispatch_request
    rv = self.handle_user_exception(e)
  File "C:\Users\georg\OneDrive\Desktop\Projects\FSND\projects\01_fyyur\starter_code\lib\site-packages\flask\app.py", line 1523, in full_dispatch_request
    rv = self.dispatch_request()
  File "C:\Users\georg\OneDrive\Desktop\Projects\FSND\projects\01_fyyur\starter_code\lib\site-packages\flask\app.py", line 1509, in dispatch_request
    return self.ensure_sync(self.view_functions[rule.endpoint])(**req.view_args)
  File "C:\Users\georg\OneDrive\Desktop\Projects\FSND\projects\01_fyyur\starter_code\app.py", line 61, in index
    recent_artists = Artist.query.order_by(Artist.id.desc()).limit(3).all()
  File "C:\Users\georg\OneDrive\Desktop\Projects\FSND\projects\01_fyyur\starter_code\lib\site-packages\sqlalchemy\orm\query.py", line 2768, in all
    return self._iter().all()
  File "C:\Users\georg\OneDrive\Desktop\Projects\FSND\projects\01_fyyur\starter_code\lib\site-packages\sqlalchemy\orm\query.py", line 2903, in _iter
    result = self.session.execute(
  File "C:\Users\georg\OneDrive\Desktop\Projects\FSND\projects\01_fyyur\starter_code\lib\site-packages\sqlalchemy\orm\session.py", line 1696, in execute
    result = conn._execute_20(statement, params or {}, execution_options)
  File "C:\Users\georg\OneDrive\Desktop\Projects\FSND\projects\01_fyyur\starter_code\lib\site-packages\sqlalchemy\engine\base.py", line 1631, in _execute_20
    return meth(self, args_10style, kwargs_10style, execution_options)
  File "C:\Users\georg\OneDrive\Desktop\Projects\FSND\projects\01_fyyur\starter_code\lib\site-packages\sqlalchemy\sql\elements.py", line 325, in _execute_on_connection
    return connection._execute_clauseelement(
  File "C:\Users\georg\OneDrive\Desktop\Projects\FSND\projects\01_fyyur\starter_code\lib\site-packages\sqlalchemy\engine\base.py", line 1498, in _execute_clauseelement
    ret = self._execute_context(
  File "C:\Users\georg\OneDrive\Desktop\Projects\FSND\projects\01_fyyur\starter_code\lib\site-packages\sqlalchemy\engine\base.py", line 1862, in _execute_context
    self._handle_dbapi_exception(
  File "C:\Users\georg\OneDrive\Desktop\Projects\FSND\projects\01_fyyur\starter_code\lib\site-packages\sqlalchemy\engine\base.py", line 2043, in _handle_dbapi_exception
    util.raise_(
  File "C:\Users\georg\OneDrive\Desktop\Projects\FSND\projects\01_fyyur\starter_code\lib\site-packages\sqlalchemy\util\compat.py", line 207, in raise_
    raise exception
  File "C:\Users\georg\OneDrive\Desktop\Projects\FSND\projects\01_fyyur\starter_code\lib\site-packages\sqlalchemy\engine\base.py", line 1819, in _execute_context
    self.dialect.do_execute(
  File "C:\Users\georg\OneDrive\Desktop\Projects\FSND\projects\01_fyyur\starter_code\lib\site-packages\sqlalchemy\engine\default.py", line 732, in do_execute
    cursor.execute(statement, parameters)
sqlalchemy.exc.OperationalError: (sqlite3.OperationalError) no such table: artist
[SQL: SELECT artist.id AS artist_id, artist.name AS artist_name, artist.city AS artist_city, artist.state AS artist_state, artist.phone AS artist_phone, artist.genres AS artist_genres, artist.image_link AS artist_image_link, artist.website_link AS artist_website_link, artist.facebook_link AS artist_facebook_link, artist.seeking_venue AS artist_seeking_venue, artist.seeking_description AS artist_seeking_description 
FROM artist ORDER BY artist.id DESC
 LIMIT ? OFFSET ?]
[parameters: (3, 0)]
(Background on this error at: https://sqlalche.me/e/14/e3q8)
2022-06-07 15:57:36,203 ERROR: Exception on /favicon.ico [GET] [in C:\Users\georg\OneDrive\Desktop\Projects\FSND\projects\01_fyyur\starter_code\lib\site-packages\flask\app.py:1455]
Traceback (most recent call last):
  File "C:\Users\georg\OneDrive\Desktop\Projects\FSND\projects\01_fyyur\starter_code\lib\site-packages\flask\app.py", line 1523, in full_dispatch_request
    rv = self.dispatch_request()
  File "C:\Users\georg\OneDrive\Desktop\Projects\FSND\projects\01_fyyur\starter_code\lib\site-packages\flask\app.py", line 1499, in dispatch_request
    self.raise_routing_exception(req)
  File "C:\Users\georg\OneDrive\Desktop\Projects\FSND\projects\01_fyyur\starter_code\lib\site-packages\flask\app.py", line 1481, in raise_routing_exception
    raise request.routing_exception  # type: ignore
  File "C:\Users\georg\OneDrive\Desktop\Projects\FSND\projects\01_fyyur\starter_code\lib\site-packages\flask\ctx.py", line 397, in match_request
    result = self.url_adapter.match(return_rule=True)  # type: ignore
  File "C:\Users\georg\OneDrive\Desktop\Projects\FSND\projects\01_fyyur\starter_code\lib\site-packages\werkzeug\routing.py", line 2028, in match
    raise NotFound()
werkzeug.exceptions.NotFound: 404 Not Found: The requested URL was not found on the server. If you entered the URL manually please check your spelling and try again.

During handling of the above exception, another exception occurred:

Traceback (most recent call last):
  File "C:\Users\georg\OneDrive\Desktop\Projects\FSND\projects\01_fyyur\starter_code\lib\site-packages\flask\app.py", line 2077, in wsgi_app
    response = self.full_dispatch_request()
  File "C:\Users\georg\OneDrive\Desktop\Projects\FSND\projects\01_fyyur\starter_code\lib\site-packages\flask\app.py", line 1525, in full_dispatch_request
    rv = self.handle_user_exception(e)
  File "C:\Users\georg\OneDrive\Desktop\Projects\FSND\projects\01_fyyur\starter_code\lib\site-packages\flask\app.py", line 1384, in handle_user_exception
    return self.handle_http_exception(e)
  File "C:\Users\georg\OneDrive\Desktop\Projects\FSND\projects\01_fyyur\starter_code\lib\site-packages\flask\app.py", line 1324, in handle_http_exception
    return self.ensure_sync(handler)(e)
  File "C:\Users\georg\OneDrive\Desktop\Projects\FSND\projects\01_fyyur\starter_code\app.py", line 451, in not_found_error
    return render_template('errors/404.html'), 404
  File "C:\Users\georg\OneDrive\Desktop\Projects\FSND\projects\01_fyyur\starter_code\lib\site-packages\flask\templating.py", line 148, in render_template
    return _render(
  File "C:\Users\georg\OneDrive\Desktop\Projects\FSND\projects\01_fyyur\starter_code\lib\site-packages\flask\templating.py", line 128, in _render
    rv = template.render(context)
  File "C:\Users\georg\OneDrive\Desktop\Projects\FSND\projects\01_fyyur\starter_code\lib\site-packages\jinja2\environment.py", line 1289, in render
    self.environment.handle_exception()
  File "C:\Users\georg\OneDrive\Desktop\Projects\FSND\projects\01_fyyur\starter_code\lib\site-packages\jinja2\environment.py", line 924, in handle_exception
    raise rewrite_traceback_stack(source=source)
  File "C:\Users\georg\OneDrive\Desktop\Projects\FSND\projects\01_fyyur\starter_code\templates\errors\404.html", line 1, in <module>
    {% extends 'layouts/main.html' %}
  File "C:\Users\georg\OneDrive\Desktop\Projects\FSND\projects\01_fyyur\starter_code\templates\layouts\main.html", line 81, in <module>
    <li {% if request.endpoint == 'venues' %} class="active" {% endif %}><a href="{{ url_for('venues') }}">Venues</a></li>
  File "C:\Users\georg\OneDrive\Desktop\Projects\FSND\projects\01_fyyur\starter_code\lib\site-packages\flask\helpers.py", line 336, in url_for
    return appctx.app.handle_url_build_error(error, endpoint, values)
  File "C:\Users\georg\OneDrive\Desktop\Projects\FSND\projects\01_fyyur\starter_code\lib\site-packages\flask\helpers.py", line 323, in url_for
    rv = url_adapter.build(
  File "C:\Users\georg\OneDrive\Desktop\Projects\FSND\projects\01_fyyur\starter_code\lib\site-packages\werkzeug\routing.py", line 2301, in build
    raise BuildError(endpoint, values, method, self)
werkzeug.routing.BuildError: Could not build url for endpoint 'venues'. Did you mean 'venue.venues' instead?
2022-06-07 15:58:08,010 INFO: errors [in C:\Users\georg\OneDrive\Desktop\Projects\FSND\projects\01_fyyur\starter_code\app.py:479]
2022-06-07 15:58:26,752 INFO: errors [in C:\Users\georg\OneDrive\Desktop\Projects\FSND\projects\01_fyyur\starter_code\app.py:479]
2022-06-07 15:58:29,067 INFO: errors [in C:\Users\georg\OneDrive\Desktop\Projects\FSND\projects\01_fyyur\starter_code\app.py:479]
2022-06-07 16:04:39,163 INFO: errors [in C:\Users\georg\OneDrive\Desktop\Projects\FSND\projects\01_fyyur\starter_code\app.py:479]
2022-06-07 16:04:51,917 INFO: errors [in C:\Users\georg\OneDrive\Desktop\Projects\FSND\projects\01_fyyur\starter_code\app.py:479]
2022-06-07 16:09:08,505 INFO: errors [in C:\Users\georg\OneDrive\Desktop\Projects\FSND\projects\01_fyyur\starter_code\app.py:479]
2022-06-07 16:09:11,089 INFO: errors [in C:\Users\georg\OneDrive\Desktop\Projects\FSND\projects\01_fyyur\starter_code\app.py:479]
2022-06-07 16:12:34,106 INFO: errors [in C:\Users\georg\OneDrive\Desktop\Projects\FSND\projects\01_fyyur\starter_code\app.py:479]
2022-06-08 01:52:21,689 INFO: errors [in C:\Users\georg\OneDrive\Desktop\Projects\FSND\projects\01_fyyur\starter_code\app.py:478]
2022-06-08 02:03:27,400 INFO: errors [in C:\Users\georg\OneDrive\Desktop\Projects\FSND\projects\01_fyyur\starter_code\app.py:478]
2022-06-08 02:03:37,138 INFO: errors [in C:\Users\georg\OneDrive\Desktop\Projects\FSND\projects\01_fyyur\starter_code\app.py:478]
